Workbook
Name Slicer_Customer_Type: #N/A
Name Slicer_Monthwise_Order: #N/A
Name Slicer_Payment_Method: #N/A
Name Slicer_Region: #N/A

Sheet Data
A1: Order ID | B1: Order Date | C1: Monthwise Order | D1: Delivery Date | E1: Cancel Date | F1: Customer ID | G1: Customer Name | H1: Customer Type | I1: State | J1: City | K1: Product ID | L1: Region | M1: Product Name | N1: Category | O1: Cost Price/Unit | P1: Sale Price/Unit | Q1: Quantity | R1: Total Amount | S1: Payment Method | T1: Delivery Status | U1: Fulfillment Partner | V1: Avg. Delivery Time | W1: Delivery Performance | X1: Target Sales(region) | Y1: Sales Achieved (region) | Z1: Total Cancelled Orders | AA1: Total Fast delivery | AB1: Total Slow Deliveries | AC1: Fast Delivery percentage | AD1: Cancelled Rate
A2: ORD0001 | B2: 45291 | C2: Dec | E2: 45293 | F2: CUST021 | G2: Zoe Mitchell | H2: Individual | I2: Texas | J2: Austin | K2: PROD012 | L2: North | M2: Lamp | N2: Home | O2: 42 | P2: 44 | Q2: 1 | R2: 44 | S2: Apple Pay | T2: Cancelled | U2: DHL | V2: =IF(DATEDIF($B2,$D2,"D")>0,DATEDIF($B2,$D2,"D"),"Not Delivered") -> Not Delivered | W2: =IF(AND(DATEDIF($B2,$D2,"D")>0,DATEDIF($B2,$D2,"D")<=2),"Fast",IF(AND(DATEDIF($B2,$D2,"D")>0,DATEDIF($B2,$D2,"D")>2,$T2="Delivered"),"Slow",IF(T2="In Transit","Slow","Cancelled Order"))) -> Cancelled Order | X2: =_xlfn.XLOOKUP($L$2,'Regional goal'!$A$3:$A$7,'Regional goal'!$B$3:$B$7) -> #NAME? | Y2: =_xlfn.XLOOKUP($L$2,'Regional goal'!$A$3:$A$7,'Regional goal'!$C$3:$C$7) -> #NAME? | Z2: =COUNTIFS(T2:T101,"Cancelled",L2:L101,"North") -> 10 | AA2: 3 | AB2: 12 | AC2: =AA2/(AA2+AB2) -> 0.2 | AD2: =Z2/30 -> 0.33333333
A3: ORD0002 | B3: 44979 | C3: Feb | D3: 44981 | F3: CUST029 | G3: Ava White | H3: Individual | I3: Florida | J3: Miami | K3: PROD018 | L3: East | M3: Doll House | N3: Toys | O3: 89 | P3: 96 | Q3: 4 | R3: 384 | S3: Credit Card | T3: Delivered | U3: DHL | V3: =IF(DATEDIF($B3,$D3,"D")>0,DATEDIF($B3,$D3,"D"),"Not Delivered") -> 2 | W3: =IF(AND(DATEDIF($B3,$D3,"D")>0,DATEDIF($B3,$D3,"D")<=2),"Fast",IF(AND(DATEDIF($B3,$D3,"D")>0,DATEDIF($B3,$D3,"D")>2,$T3="Delivered"),"Slow",IF(T3="In Transit","Slow","Cancelled Order"))) -> Fast | X3: =_xlfn.XLOOKUP($L$3,'Regional goal'!$A$3:$A$7,'Regional goal'!$B$3:$B$7) -> #NAME? | Y3: =_xlfn.XLOOKUP($L$3,'Regional goal'!$A$3:$A$7,'Regional goal'!$C$3:$C$7) -> #NAME? | Z3: =COUNTIFS(T2:T101,"Cancelled",L2:L101,"East") -> 3 | AA3: 2 | AB3: 13 | AC3: =AA3/(AA3+AB3) -> 0.13333333 | AD3: =Z3/30 -> 0.1
A4: ORD0003 | B4: 45210 | C4: Oct | F4: CUST021 | G4: Zoe Mitchell | H4: Individual | I4: Texas | J4: Austin | K4: PROD013 | L4: South | M4: Vacuum Cleaner | N4: Home | O4: 185 | P4: 194 | Q4: 4 | R4: 776 | S4: Credit Card | T4: In Transit | U4: USPS | V4: =IF(DATEDIF($B4,$D4,"D")>0,DATEDIF($B4,$D4,"D"),"Not Delivered") -> Not Delivered | W4: =IF(AND(DATEDIF($B4,$D4,"D")>0,DATEDIF($B4,$D4,"D")<=2),"Fast",IF(AND(DATEDIF($B4,$D4,"D")>0,DATEDIF($B4,$D4,"D")>2,$T4="Delivered"),"Slow",IF(T4="In Transit","Slow","Cancelled Order"))) -> Slow | X4: =_xlfn.XLOOKUP($L$4,'Regional goal'!$A$3:$A$7,'Regional goal'!$B$3:$B$7) -> #NAME? | Y4: =_xlfn.XLOOKUP($L$4,'Regional goal'!$A$3:$A$7,'Regional goal'!$C$3:$C$7) -> #NAME? | Z4: =COUNTIFS(T2:T101,"Cancelled",L2:L101,"South") -> 4 | AA4: 3 | AB4: 13 | AC4: =AA4/(AA4+AB4) -> 0.1875 | AD4: =Z4/30 -> 0.13333333
A5: ORD0004 | B5: 45051 | C5: May | E5: 45057 | F5: CUST044 | G5: Grace Ward | H5: Business | I5: Arizona | J5: Phoenix | K5: PROD013 | L5: North | M5: Vacuum Cleaner | N5: Home | O5: 185 | P5: 196 | Q5: 3 | R5: 588 | S5: PayPal | T5: Cancelled | U5: UPS | V5: =IF(DATEDIF($B5,$D5,"D")>0,DATEDIF($B5,$D5,"D"),"Not Delivered") -> Not Delivered | W5: =IF(AND(DATEDIF($B5,$D5,"D")>0,DATEDIF($B5,$D5,"D")<=2),"Fast",IF(AND(DATEDIF($B5,$D5,"D")>0,DATEDIF($B5,$D5,"D")>2,$T5="Delivered"),"Slow",IF(T5="In Transit","Slow","Cancelled Order"))) -> Cancelled Order
A6: ORD0005 | B6: 44959 | C6: Feb | D6: 44962 | F6: CUST027 | G6: Hazel Brooks | H6: Individual | I6: Washington | J6: Seattle | K6: PROD010 | L6: North | M6: Jeans | N6: Fashion | O6: 55 | P6: 59 | Q6: 1 | R6: 59 | S6: PayPal | T6: Delivered | U6: Amazon Logistics | V6: =IF(DATEDIF($B6,$D6,"D")>0,DATEDIF($B6,$D6,"D"),"Not Delivered") -> 3 | W6: =IF(AND(DATEDIF($B6,$D6,"D")>0,DATEDIF($B6,$D6,"D")<=2),"Fast",IF(AND(DATEDIF($B6,$D6,"D")>0,DATEDIF($B6,$D6,"D")>2,$T6="Delivered"),"Slow",IF(T6="In Transit","Slow","Cancelled Order"))) -> Slow
A7: ORD0006 | B7: 45231 | C7: Nov | E7: 45232 | F7: CUST009 | G7: Jackson Allen | H7: Business | I7: Washington | J7: Seattle | K7: PROD010 | L7: North | M7: Jeans | N7: Fashion | O7: 55 | P7: 58 | Q7: 4 | R7: 232 | S7: Amazon Pay | T7: Cancelled | U7: DHL | V7: =IF(DATEDIF($B7,$D7,"D")>0,DATEDIF($B7,$D7,"D"),"Not Delivered") -> Not Delivered | W7: =IF(AND(DATEDIF($B7,$D7,"D")>0,DATEDIF($B7,$D7,"D")<=2),"Fast",IF(AND(DATEDIF($B7,$D7,"D")>0,DATEDIF($B7,$D7,"D")>2,$T7="Delivered"),"Slow",IF(T7="In Transit","Slow","Cancelled Order"))) -> Cancelled Order
A8: ORD0007 | B8: 45152 | C8: Aug | E8: 45156 | F8: CUST042 | G8: Noah Wilson | H8: Prime | I8: Texas | J8: Austin | K8: PROD020 | L8: Central | M8: Bluetooth Speaker | N8: Electronics | O8: 99 | P8: 105 | Q8: 3 | R8: 315 | S8: Debit Card | T8: Cancelled | U8: DHL | V8: =IF(DATEDIF($B8,$D8,"D")>0,DATEDIF($B8,$D8,"D"),"Not Delivered") -> Not Delivered | W8: =IF(AND(DATEDIF($B8,$D8,"D")>0,DATEDIF($B8,$D8,"D")<=2),"Fast",IF(AND(DATEDIF($B8,$D8,"D")>0,DATEDIF($B8,$D8,"D")>2,$T8="Delivered"),"Slow",IF(T8="In Transit","Slow","Cancelled Order"))) -> Cancelled Order | X8: =_xlfn.XLOOKUP(L8,'Regional goal'!$A$3:$A$7,'Regional goal'!$B$3:$B$7) -> #NAME? | Y8: =_xlfn.XLOOKUP($L$8,'Regional goal'!$A$3:$A$7,'Regional goal'!$C$3:$C$7) -> #NAME? | Z8: =COUNTIFS(T2:T101,"Cancelled",L2:L101,"Central") -> 5 | AA8: 1 | AB8: 8 | AC8: =AA8/(AA8+AB8) -> 0.11111111 | AD8: =Z8/30 -> 0.16666667
A9: ORD0008 | B9: 45017 | C9: Apr | E9: 45022 | F9: CUST019 | G9: Ava Robinson | H9: Prime | I9: Washington | J9: Seattle | K9: PROD021 | L9: West | M9: Wall Clock | N9: Home | O9: 34 | P9: 37 | Q9: 5 | R9: 185 | S9: PayPal | T9: Cancelled | U9: DHL | V9: =IF(DATEDIF($B9,$D9,"D")>0,DATEDIF($B9,$D9,"D"),"Not Delivered") -> Not Delivered | W9: =IF(AND(DATEDIF($B9,$D9,"D")>0,DATEDIF($B9,$D9,"D")<=2),"Fast",IF(AND(DATEDIF($B9,$D9,"D")>0,DATEDIF($B9,$D9,"D")>2,$T9="Delivered"),"Slow",IF(T9="In Transit","Slow","Cancelled Order"))) -> Cancelled Order | X9: =_xlfn.XLOOKUP($L$9,'Regional goal'!$A$3:$A$7,'Regional goal'!$B$3:$B$7) -> #NAME? | Y9: =_xlfn.XLOOKUP($L$9,'Regional goal'!$A$3:$A$7,'Regional goal'!$C$3:$C$7) -> #NAME? | Z9: =COUNTIFS(T2:T101,"Cancelled",L2:L101,"West") -> 8 | AA9: 2 | AB9: 13 | AC9: =AA9/(AA9+AB9) -> 0.13333333 | AD9: =Z9/30 -> 0.26666667
A10: ORD0009 | B10: 45128 | C10: Jul | F10: CUST013 | G10: Olivia Martinez | H10: Prime | I10: Washington | J10: Seattle | K10: PROD019 | L10: Central | M10: Formal Shirt | N10: Fashion | O10: 40 | P10: 44 | Q10: 2 | R10: 88 | S10: Credit Card | T10: In Transit | U10: Amazon Logistics | V10: =IF(DATEDIF($B10,$D10,"D")>0,DATEDIF($B10,$D10,"D"),"Not Delivered") -> Not Delivered | W10: =IF(AND(DATEDIF($B10,$D10,"D")>0,DATEDIF($B10,$D10,"D")<=2),"Fast",IF(AND(DATEDIF($B10,$D10,"D")>0,DATEDIF($B10,$D10,"D")>2,$T10="Delivered"),"Slow",IF(T10="In Transit","Slow","Cancelled Order"))) -> Slow
A11: ORD0010 | B11: 45289 | C11: Dec | F11: CUST019 | G11: Ava Robinson | H11: Prime | I11: Washington | J11: Seattle | K11: PROD003 | L11: South | M11: Cookware Set | N11: Home | O11: 129 | P11: 141 | Q11: 4 | R11: 564 | S11: Debit Card | T11: In Transit | U11: DHL | V11: =IF(DATEDIF($B11,$D11,"D")>0,DATEDIF($B11,$D11,"D"),"Not Delivered") -> Not Delivered | W11: =IF(AND(DATEDIF($B11,$D11,"D")>0,DATEDIF($B11,$D11,"D")<=2),"Fast",IF(AND(DATEDIF($B11,$D11,"D")>0,DATEDIF($B11,$D11,"D")>2,$T11="Delivered"),"Slow",IF(T11="In Transit","Slow","Cancelled Order"))) -> Slow
A12: ORD0011 | B12: 45050 | C12: May | E12: 45054 | F12: CUST046 | G12: Emily Johnson | H12: Prime | I12: Illinois | J12: Chicago | K12: PROD014 | L12: South | M12: Smartwatch | N12: Electronics | O12: 229 | P12: 249 | Q12: 1 | R12: 249 | S12: Amazon Pay | T12: Cancelled | U12: USPS | V12: =IF(DATEDIF($B12,$D12,"D")>0,DATEDIF($B12,$D12,"D"),"Not Delivered") -> Not Delivered | W12: =IF(AND(DATEDIF($B12,$D12,"D")>0,DATEDIF($B12,$D12,"D")<=2),"Fast",IF(AND(DATEDIF($B12,$D12,"D")>0,DATEDIF($B12,$D12,"D")>2,$T12="Delivered"),"Slow",IF(T12="In Transit","Slow","Cancelled Order"))) -> Cancelled Order
A13: ORD0012 | B13: 45132 | C13: Jul | F13: CUST045 | G13: Emily Johnson | H13: Individual | I13: Texas | J13: Austin | K13: PROD014 | L13: Central | M13: Smartwatch | N13: Electronics | O13: 229 | P13: 247 | Q13: 3 | R13: 741 | S13: Amazon Pay | T13: In Transit | U13: FedEx | V13: =IF(DATEDIF($B13,$D13,"D")>0,DATEDIF($B13,$D13,"D"),"Not Delivered") -> Not Delivered | W13: =IF(AND(DATEDIF($B13,$D13,"D")>0,DATEDIF($B13,$D13,"D")<=2),"Fast",IF(AND(DATEDIF($B13,$D13,"D")>0,DATEDIF($B13,$D13,"D")>2,$T13="Delivered"),"Slow",IF(T13="In Transit","Slow","Cancelled Order"))) -> Slow
A14: ORD0013 | B14: 44982 | C14: Feb | E14: 44985 | F14: CUST023 | G14: Charlotte Reed | H14: Individual | I14: Texas | J14: Austin | K14: PROD006 | L14: Central | M14: Shoes | N14: Fashion | O14: 89 | P14: 96 | Q14: 1 | R14: 96 | S14: Apple Pay | T14: Cancelled | U14: Amazon Logistics | V14: =IF(DATEDIF($B14,$D14,"D")>0,DATEDIF($B14,$D14,"D"),"Not Delivered") -> Not Delivered | W14: =IF(AND(DATEDIF($B14,$D14,"D")>0,DATEDIF($B14,$D14,"D")<=2),"Fast",IF(AND(DATEDIF($B14,$D14,"D")>0,DATEDIF($B14,$D14,"D")>2,$T14="Delivered"),"Slow",IF(T14="In Transit","Slow","Cancelled Order"))) -> Cancelled Order
A15: ORD0014 | B15: 44981 | C15: Feb | E15: 44982 | F15: CUST033 | G15: Hazel Rivera | H15: Business | I15: Arizona | J15: Phoenix | K15: PROD017 | L15: West | M15: Gaming Mouse | N15: Electronics | O15: 69 | P15: 74 | Q15: 5 | R15: 370 | S15: Apple Pay | T15: Cancelled | U15: Amazon Logistics | V15: =IF(DATEDIF($B15,$D15,"D")>0,DATEDIF($B15,$D15,"D"),"Not Delivered") -> Not Delivered | W15: =IF(AND(DATEDIF($B15,$D15,"D")>0,DATEDIF($B15,$D15,"D")<=2),"Fast",IF(AND(DATEDIF($B15,$D15,"D")>0,DATEDIF($B15,$D15,"D")>2,$T15="Delivered"),"Slow",IF(T15="In Transit","Slow","Cancelled Order"))) -> Cancelled Order
A16: ORD0015 | B16: 45164 | C16: Aug | E16: 45171 | F16: CUST033 | G16: Hazel Rivera | H16: Business | I16: Arizona | J16: Phoenix | K16: PROD005 | L16: South | M16: T-Shirt | N16: Fashion | O16: 25 | P16: 27 | Q16: 1 | R16: 27 | S16: Credit Card | T16: Cancelled | U16: Amazon Logistics | V16: =IF(DATEDIF($B16,$D16,"D")>0,DATEDIF($B16,$D16,"D"),"Not Delivered") -> Not Delivered | W16: =IF(AND(DATEDIF($B16,$D16,"D")>0,DATEDIF($B16,$D16,"D")<=2),"Fast",IF(AND(DATEDIF($B16,$D16,"D")>0,DATEDIF($B16,$D16,"D")>2,$T16="Delivered"),"Slow",IF(T16="In Transit","Slow","Cancelled Order"))) -> Cancelled Order
A17: ORD0016 | B17: 44970 | C17: Feb | F17: CUST047 | G17: Scarlett Murphy | H17: Individual | I17: Illinois | J17: Chicago | K17: PROD005 | L17: South | M17: T-Shirt | N17: Fashion | O17: 25 | P17: 27 | Q17: 3 | R17: 81 | S17: Debit Card | T17: In Transit | U17: Amazon Logistics | V17: =IF(DATEDIF($B17,$D17,"D")>0,DATEDIF($B17,$D17,"D"),"Not Delivered") -> Not Delivered | W17: =IF(AND(DATEDIF($B17,$D17,"D")>0,DATEDIF($B17,$D17,"D")<=2),"Fast",IF(AND(DATEDIF($B17,$D17,"D")>0,DATEDIF($B17,$D17,"D")>2,$T17="Delivered"),"Slow",IF(T17="In Transit","Slow","Cancelled Order"))) -> Slow
A18: ORD0017 | B18: 45105 | C18: Jun | D18: 45108 | F18: CUST045 | G18: Emily Johnson | H18: Individual | I18: Texas | J18: Austin | K18: PROD015 | L18: East | M18: Novel | N18: Books | O18: 20 | P18: 21 | Q18: 3 | R18: 63 | S18: Credit Card | T18: Delivered | U18: DHL | V18: =IF(DATEDIF($B18,$D18,"D")>0,DATEDIF($B18,$D18,"D"),"Not Delivered") -> 3 | W18: =IF(AND(DATEDIF($B18,$D18,"D")>0,DATEDIF($B18,$D18,"D")<=2),"Fast",IF(AND(DATEDIF($B18,$D18,"D")>0,DATEDIF($B18,$D18,"D")>2,$T18="Delivered"),"Slow",IF(T18="In Transit","Slow","Cancelled Order"))) -> Slow
A19: ORD0018 | B19: 45258 | C19: Nov | F19: CUST011 | G19: Mason Hall | H19: Business | I19: Florida | J19: Miami | K19: PROD008 | L19: West | M19: Textbook | N19: Books | O19: 65 | P19: 70 | Q19: 5 | R19: 350 | S19: PayPal | T19: In Transit | U19: Amazon Logistics | V19: =IF(DATEDIF($B19,$D19,"D")>0,DATEDIF($B19,$D19,"D"),"Not Delivered") -> Not Delivered | W19: =IF(AND(DATEDIF($B19,$D19,"D")>0,DATEDIF($B19,$D19,"D")<=2),"Fast",IF(AND(DATEDIF($B19,$D19,"D")>0,DATEDIF($B19,$D19,"D")>2,$T19="Delivered"),"Slow",IF(T19="In Transit","Slow","Cancelled Order"))) -> Slow
A20: ORD0019 | B20: 45163 | C20: Aug | F20: CUST041 | G20: Jacob Price | H20: Business | I20: Texas | J20: Austin | K20: PROD006 | L20: South | M20: Shoes | N20: Fashion | O20: 89 | P20: 94 | Q20: 4 | R20: 376 | S20: Credit Card | T20: In Transit | U20: USPS | V20: =IF(DATEDIF($B20,$D20,"D")>0,DATEDIF($B20,$D20,"D"),"Not Delivered") -> Not Delivered | W20: =IF(AND(DATEDIF($B20,$D20,"D")>0,DATEDIF($B20,$D20,"D")<=2),"Fast",IF(AND(DATEDIF($B20,$D20,"D")>0,DATEDIF($B20,$D20,"D")>2,$T20="Delivered"),"Slow",IF(T20="In Transit","Slow","Cancelled Order"))) -> Slow
A21: ORD0020 | B21: 45028 | C21: Apr | F21: CUST025 | G21: Emma King | H21: Individual | I21: Florida | J21: Miami | K21: PROD001 | L21: North | M21: Smartphone | N21: Electronics | O21: 749 | P21: 813 | Q21: 2 | R21: 1626 | S21: Credit Card | T21: In Transit | U21: FedEx | V21: =IF(DATEDIF($B21,$D21,"D")>0,DATEDIF($B21,$D21,"D"),"Not Delivered") -> Not Delivered | W21: =IF(AND(DATEDIF($B21,$D21,"D")>0,DATEDIF($B21,$D21,"D")<=2),"Fast",IF(AND(DATEDIF($B21,$D21,"D")>0,DATEDIF($B21,$D21,"D")>2,$T21="Delivered"),"Slow",IF(T21="In Transit","Slow","Cancelled Order"))) -> Slow
A22: ORD0021 | B22: 45201 | C22: Oct | F22: CUST013 | G22: Olivia Martinez | H22: Prime | I22: Washington | J22: Seattle | K22: PROD015 | L22: Central | M22: Novel | N22: Books | O22: 20 | P22: 21 | Q22: 4 | R22: 84 | S22: PayPal | T22: In Transit | U22: Amazon Logistics | V22: =IF(DATEDIF($B22,$D22,"D")>0,DATEDIF($B22,$D22,"D"),"Not Delivered") -> Not Delivered | W22: =IF(AND(DATEDIF($B22,$D22,"D")>0,DATEDIF($B22,$D22,"D")<=2),"Fast",IF(AND(DATEDIF($B22,$D22,"D")>0,DATEDIF($B22,$D22,"D")>2,$T22="Delivered"),"Slow",IF(T22="In Transit","Slow","Cancelled Order"))) -> Slow
A23: ORD0022 | B23: 45239 | C23: Nov | F23: CUST023 | G23: Charlotte Reed | H23: Individual | I23: Texas | J23: Austin | K23: PROD012 | L23: West | M23: Lamp | N23: Home | O23: 42 | P23: 46 | Q23: 5 | R23: 230 | S23: PayPal | T23: In Transit | U23: USPS | V23: =IF(DATEDIF($B23,$D23,"D")>0,DATEDIF($B23,$D23,"D"),"Not Delivered") -> Not Delivered | W23: =IF(AND(DATEDIF($B23,$D23,"D")>0,DATEDIF($B23,$D23,"D")<=2),"Fast",IF(AND(DATEDIF($B23,$D23,"D")>0,DATEDIF($B23,$D23,"D")>2,$T23="Delivered"),"Slow",IF(T23="In Transit","Slow","Cancelled Order"))) -> Slow
A24: ORD0023 | B24: 44970 | C24: Feb | E24: 44971 | F24: CUST016 | G24: Elijah Lewis | H24: Prime | I24: Arizona | J24: Phoenix | K24: PROD010 | L24: West | M24: Jeans | N24: Fashion | O24: 55 | P24: 58 | Q24: 3 | R24: 174 | S24: Amazon Pay | T24: Cancelled | U24: Amazon Logistics | V24: =IF(DATEDIF($B24,$D24,"D")>0,DATEDIF($B24,$D24,"D"),"Not Delivered") -> Not Delivered | W24: =IF(AND(DATEDIF($B24,$D24,"D")>0,DATEDIF($B24,$D24,"D")<=2),"Fast",IF(AND(DATEDIF($B24,$D24,"D")>0,DATEDIF($B24,$D24,"D")>2,$T24="Delivered"),"Slow",IF(T24="In Transit","Slow","Cancelled Order"))) -> Cancelled Order
A25: ORD0024 | B25: 45232 | C25: Nov | D25: 45235 | F25: CUST028 | G25: Lily Bennett | H25: Business | I25: Texas | J25: Austin | K25: PROD006 | L25: West | M25: Shoes | N25: Fashion | O25: 89 | P25: 96 | Q25: 5 | R25: 480 | S25: Amazon Pay | T25: Delivered | U25: Amazon Logistics | V25: =IF(DATEDIF($B25,$D25,"D")>0,DATEDIF($B25,$D25,"D"),"Not Delivered") -> 3 | W25: =IF(AND(DATEDIF($B25,$D25,"D")>0,DATEDIF($B25,$D25,"D")<=2),"Fast",IF(AND(DATEDIF($B25,$D25,"D")>0,DATEDIF($B25,$D25,"D")>2,$T25="Delivered"),"Slow",IF(T25="In Transit","Slow","Cancelled Order"))) -> Slow
A26: ORD0025 | B26: 45074 | C26: May | D26: 45076 | F26: CUST040 | G26: Benjamin Clark | H26: Prime | I26: Texas | J26: Austin | K26: PROD002 | L26: South | M26: Action Figure | N26: Toys | O26: 39 | P26: 43 | Q26: 1 | R26: 43 | S26: Debit Card | T26: Delivered | U26: Amazon Logistics | V26: =IF(DATEDIF($B26,$D26,"D")>0,DATEDIF($B26,$D26,"D"),"Not Delivered") -> 2 | W26: =IF(AND(DATEDIF($B26,$D26,"D")>0,DATEDIF($B26,$D26,"D")<=2),"Fast",IF(AND(DATEDIF($B26,$D26,"D")>0,DATEDIF($B26,$D26,"D")>2,$T26="Delivered"),"Slow",IF(T26="In Transit","Slow","Cancelled Order"))) -> Fast
A27: ORD0026 | B27: 45214 | C27: Oct | D27: 45220 | F27: CUST027 | G27: Hazel Brooks | H27: Individual | I27: Washington | J27: Seattle | K27: PROD022 | L27: South | M27: Backpack | N27: Fashion | O27: 60 | P27: 64 | Q27: 4 | R27: 256 | S27: Debit Card | T27: Delivered | U27: USPS | V27: =IF(DATEDIF($B27,$D27,"D")>0,DATEDIF($B27,$D27,"D"),"Not Delivered") -> 6 | W27: =IF(AND(DATEDIF($B27,$D27,"D")>0,DATEDIF($B27,$D27,"D")<=2),"Fast",IF(AND(DATEDIF($B27,$D27,"D")>0,DATEDIF($B27,$D27,"D")>2,$T27="Delivered"),"Slow",IF(T27="In Transit","Slow","Cancelled Order"))) -> Slow
A28: ORD0027 | B28: 44942 | C28: Jan | F28: CUST018 | G28: Grace Scott | H28: Individual | I28: Florida | J28: Miami | K28: PROD008 | L28: South | M28: Textbook | N28: Books | O28: 65 | P28: 70 | Q28: 2 | R28: 140 | S28: Amazon Pay | T28: In Transit | U28: Amazon Logistics | V28: =IF(DATEDIF($B28,$D28,"D")>0,DATEDIF($B28,$D28,"D"),"Not Delivered") -> Not Delivered | W28: =IF(AND(DATEDIF($B28,$D28,"D")>0,DATEDIF($B28,$D28,"D")<=2),"Fast",IF(AND(DATEDIF($B28,$D28,"D")>0,DATEDIF($B28,$D28,"D")>2,$T28="Delivered"),"Slow",IF(T28="In Transit","Slow","Cancelled Order"))) -> Slow
A29: ORD0028 | B29: 45208 | C29: Oct | F29: CUST018 | G29: Grace Scott | H29: Individual | I29: Florida | J29: Miami | K29: PROD018 | L29: Central | M29: Doll House | N29: Toys | O29: 89 | P29: 97 | Q29: 3 | R29: 291 | S29: Credit Card | T29: In Transit | U29: Amazon Logistics | V29: =IF(DATEDIF($B29,$D29,"D")>0,DATEDIF($B29,$D29,"D"),"Not Delivered") -> Not Delivered | W29: =IF(AND(DATEDIF($B29,$D29,"D")>0,DATEDIF($B29,$D29,"D")<=2),"Fast",IF(AND(DATEDIF($B29,$D29,"D")>0,DATEDIF($B29,$D29,"D")>2,$T29="Delivered"),"Slow",IF(T29="In Transit","Slow","Cancelled Order"))) -> Slow
A30: ORD0029 | B30: 45206 | C30: Oct | E30: 45209 | F30: CUST007 | G30: Liam Walker | H30: Prime | I30: California | J30: San Francisco | K30: PROD021 | L30: East | M30: Wall Clock | N30: Home | O30: 34 | P30: 37 | Q30: 3 | R30: 111 | S30: Apple Pay | T30: Cancelled | U30: DHL | V30: =IF(DATEDIF($B30,$D30,"D")>0,DATEDIF($B30,$D30,"D"),"Not Delivered") -> Not Delivered | W30: =IF(AND(DATEDIF($B30,$D30,"D")>0,DATEDIF($B30,$D30,"D")<=2),"Fast",IF(AND(DATEDIF($B30,$D30,"D")>0,DATEDIF($B30,$D30,"D")>2,$T30="Delivered"),"Slow",IF(T30="In Transit","Slow","Cancelled Order"))) -> Cancelled Order
A31: ORD0030 | B31: 44971 | C31: Feb | F31: CUST008 | G31: Harper Young | H31: Business | I31: Texas | J31: Dallas | K31: PROD008 | L31: North | M31: Textbook | N31: Books | O31: 65 | P31: 69 | Q31: 5 | R31: 345 | S31: Amazon Pay | T31: In Transit | U31: Amazon Logistics | V31: =IF(DATEDIF($B31,$D31,"D")>0,DATEDIF($B31,$D31,"D"),"Not Delivered") -> Not Delivered | W31: =IF(AND(DATEDIF($B31,$D31,"D")>0,DATEDIF($B31,$D31,"D")<=2),"Fast",IF(AND(DATEDIF($B31,$D31,"D")>0,DATEDIF($B31,$D31,"D")>2,$T31="Delivered"),"Slow",IF(T31="In Transit","Slow","Cancelled Order"))) -> Slow
A32: ORD0031 | B32: 45011 | C32: Mar | F32: CUST014 | G32: Harper Young | H32: Individual | I32: Illinois | J32: Chicago | K32: PROD002 | L32: North | M32: Action Figure | N32: Toys | O32: 39 | P32: 42 | Q32: 5 | R32: 210 | S32: Amazon Pay | T32: In Transit | U32: UPS | V32: =IF(DATEDIF($B32,$D32,"D")>0,DATEDIF($B32,$D32,"D"),"Not Delivered") -> Not Delivered | W32: =IF(AND(DATEDIF($B32,$D32,"D")>0,DATEDIF($B32,$D32,"D")<=2),"Fast",IF(AND(DATEDIF($B32,$D32,"D")>0,DATEDIF($B32,$D32,"D")>2,$T32="Delivered"),"Slow",IF(T32="In Transit","Slow","Cancelled Order"))) -> Slow
A33: ORD0032 | B33: 45092 | C33: Jun | E33: 45099 | F33: CUST037 | G33: Emily Johnson | H33: Individual | I33: Florida | J33: Miami | K33: PROD009 | L33: East | M33: Magazine | N33: Books | O33: 10 | P33: 11 | Q33: 5 | R33: 55 | S33: Debit Card | T33: Cancelled | U33: FedEx | V33: =IF(DATEDIF($B33,$D33,"D")>0,DATEDIF($B33,$D33,"D"),"Not Delivered") -> Not Delivered | W33: =IF(AND(DATEDIF($B33,$D33,"D")>0,DATEDIF($B33,$D33,"D")<=2),"Fast",IF(AND(DATEDIF($B33,$D33,"D")>0,DATEDIF($B33,$D33,"D")>2,$T33="Delivered"),"Slow",IF(T33="In Transit","Slow","Cancelled Order"))) -> Cancelled Order
A34: ORD0033 | B34: 45068 | C34: May | D34: 45069 | F34: CUST016 | G34: Elijah Lewis | H34: Prime | I34: Arizona | J34: Phoenix | K34: PROD005 | L34: South | M34: T-Shirt | N34: Fashion | O34: 25 | P34: 27 | Q34: 2 | R34: 54 | S34: Apple Pay | T34: Delivered | U34: USPS | V34: =IF(DATEDIF($B34,$D34,"D")>0,DATEDIF($B34,$D34,"D"),"Not Delivered") -> 1 | W34: =IF(AND(DATEDIF($B34,$D34,"D")>0,DATEDIF($B34,$D34,"D")<=2),"Fast",IF(AND(DATEDIF($B34,$D34,"D")>0,DATEDIF($B34,$D34,"D")>2,$T34="Delivered"),"Slow",IF(T34="In Transit","Slow","Cancelled Order"))) -> Fast
A35: ORD0034 | B35: 45250 | C35: Nov | F35: CUST025 | G35: Emma King | H35: Individual | I35: Florida | J35: Miami | K35: PROD015 | L35: South | M35: Novel | N35: Books | O35: 20 | P35: 21 | Q35: 1 | R35: 21 | S35: Amazon Pay | T35: In Transit | U35: DHL | V35: =IF(DATEDIF($B35,$D35,"D")>0,DATEDIF($B35,$D35,"D"),"Not Delivered") -> Not Delivered | W35: =IF(AND(DATEDIF($B35,$D35,"D")>0,DATEDIF($B35,$D35,"D")<=2),"Fast",IF(AND(DATEDIF($B35,$D35,"D")>0,DATEDIF($B35,$D35,"D")>2,$T35="Delivered"),"Slow",IF(T35="In Transit","Slow","Cancelled Order"))) -> Slow
A36: ORD0035 | B36: 45282 | C36: Dec | D36: 45286 | F36: CUST032 | G36: Luke Gray | H36: Business | I36: Texas | J36: Austin | K36: PROD011 | L36: South | M36: Headphones | N36: Electronics | O36: 159 | P36: 172 | Q36: 1 | R36: 172 | S36: PayPal | T36: Delivered | U36: USPS | V36: =IF(DATEDIF($B36,$D36,"D")>0,DATEDIF($B36,$D36,"D"),"Not Delivered") -> 4 | W36: =IF(AND(DATEDIF($B36,$D36,"D")>0,DATEDIF($B36,$D36,"D")<=2),"Fast",IF(AND(DATEDIF($B36,$D36,"D")>0,DATEDIF($B36,$D36,"D")>2,$T36="Delivered"),"Slow",IF(T36="In Transit","Slow","Cancelled Order"))) -> Slow
A37: ORD0036 | B37: 45130 | C37: Jul | F37: CUST014 | G37: Harper Young | H37: Individual | I37: Illinois | J37: Chicago | K37: PROD016 | L37: North | M37: Cookware Set Pro | N37: Home | O37: 199 | P37: 212 | Q37: 3 | R37: 636 | S37: Amazon Pay | T37: In Transit | U37: UPS | V37: =IF(DATEDIF($B37,$D37,"D")>0,DATEDIF($B37,$D37,"D"),"Not Delivered") -> Not Delivered | W37: =IF(AND(DATEDIF($B37,$D37,"D")>0,DATEDIF($B37,$D37,"D")<=2),"Fast",IF(AND(DATEDIF($B37,$D37,"D")>0,DATEDIF($B37,$D37,"D")>2,$T37="Delivered"),"Slow",IF(T37="In Transit","Slow","Cancelled Order"))) -> Slow
A38: ORD0037 | B38: 45216 | C38: Oct | D38: 45221 | F38: CUST044 | G38: Grace Ward | H38: Business | I38: Arizona | J38: Phoenix | K38: PROD002 | L38: East | M38: Action Figure | N38: Toys | O38: 39 | P38: 41 | Q38: 4 | R38: 164 | S38: Credit Card | T38: Delivered | U38: Amazon Logistics | V38: =IF(DATEDIF($B38,$D38,"D")>0,DATEDIF($B38,$D38,"D"),"Not Delivered") -> 5 | W38: =IF(AND(DATEDIF($B38,$D38,"D")>0,DATEDIF($B38,$D38,"D")<=2),"Fast",IF(AND(DATEDIF($B38,$D38,"D")>0,DATEDIF($B38,$D38,"D")>2,$T38="Delivered"),"Slow",IF(T38="In Transit","Slow","Cancelled Order"))) -> Slow
A39: ORD0038 | B39: 45160 | C39: Aug | E39: 45162 | F39: CUST028 | G39: Lily Bennett | H39: Business | I39: Texas | J39: Austin | K39: PROD007 | L39: North | M39: Puzzle | N39: Toys | O39: 29 | P39: 32 | Q39: 2 | R39: 64 | S39: Debit Card | T39: Cancelled | U39: FedEx | V39: =IF(DATEDIF($B39,$D39,"D")>0,DATEDIF($B39,$D39,"D"),"Not Delivered") -> Not Delivered | W39: =IF(AND(DATEDIF($B39,$D39,"D")>0,DATEDIF($B39,$D39,"D")<=2),"Fast",IF(AND(DATEDIF($B39,$D39,"D")>0,DATEDIF($B39,$D39,"D")>2,$T39="Delivered"),"Slow",IF(T39="In Transit","Slow","Cancelled Order"))) -> Cancelled Order
A40: ORD0039 | B40: 45262 | C40: Dec | F40: CUST024 | G40: Scarlett Murphy | H40: Business | I40: Florida | J40: Miami | K40: PROD022 | L40: East | M40: Backpack | N40: Fashion | O40: 60 | P40: 66 | Q40: 2 | R40: 132 | S40: Apple Pay | T40: In Transit | U40: DHL | V40: =IF(DATEDIF($B40,$D40,"D")>0,DATEDIF($B40,$D40,"D"),"Not Delivered") -> Not Delivered | W40: =IF(AND(DATEDIF($B40,$D40,"D")>0,DATEDIF($B40,$D40,"D")<=2),"Fast",IF(AND(DATEDIF($B40,$D40,"D")>0,DATEDIF($B40,$D40,"D")>2,$T40="Delivered"),"Slow",IF(T40="In Transit","Slow","Cancelled Order"))) -> Slow
...

Sheet Regional goal
A2: Region | B2: Sales Target | C2: Sales Achieved | D2: % Sales Target vs Sales Achive | F2: Region | G2: Fast Delivery | H2: Slow Delivery | I2: % fast Delivery
A3: Central | B3: 97500 | C3: =SUMIF(Data!$L$2:$L$101,A3,Data!$R$2:$R$101) -> 5456 | D3: =C3/B3 -> 0.055958974 | F3: Central | G3: =COUNTIFS(Data!$L$2:$L$101,$F3,Data!$W$2:$W$101,Data!$W$3) -> 1 | H3: =COUNTIFS(Data!$L$2:$L$101,$F3,Data!$W$2:$W$101,Data!$W$4) -> 8 | I3: =(G3/(G3+H3))*100 -> 11.111111
A4: East | B4: 50500 | C4: =SUMIF(Data!$L$2:$L$101,A4,Data!$R$2:$R$101) -> 3635 | D4: =C4/B4 -> 0.071980198 | F4: East | G4: =COUNTIFS(Data!$L$2:$L$101,$F4,Data!$W$2:$W$101,Data!$W$3) -> 2 | H4: =COUNTIFS(Data!$L$2:$L$101,$F4,Data!$W$2:$W$101,Data!$W$4) -> 13 | I4: =(G4/(G4+H4))*100 -> 13.333333
A5: North | B5: 105000 | C5: =SUMIF(Data!$L$2:$L$101,A5,Data!$R$2:$R$101) -> 10491 | D5: =C5/B5 -> 0.099914286 | F5: North | G5: =COUNTIFS(Data!$L$2:$L$101,$F5,Data!$W$2:$W$101,Data!$W$3) -> 3 | H5: =COUNTIFS(Data!$L$2:$L$101,$F5,Data!$W$2:$W$101,Data!$W$4) -> 12 | I5: =(G5/(G5+H5))*100 -> 20
A6: South | B6: 91500 | C6: =SUMIF(Data!$L$2:$L$101,A6,Data!$R$2:$R$101) -> 7317 | D6: =C6/B6 -> 0.079967213 | F6: South | G6: =COUNTIFS(Data!$L$2:$L$101,$F6,Data!$W$2:$W$101,Data!$W$3) -> 3 | H6: =COUNTIFS(Data!$L$2:$L$101,$F6,Data!$W$2:$W$101,Data!$W$4) -> 13 | I6: =(G6/(G6+H6))*100 -> 18.75
A7: West | B7: 90750 | C7: =SUMIF(Data!$L$2:$L$101,A7,Data!$R$2:$R$101) -> 8359 | D7: =C7/B7 -> 0.092110193 | F7: West | G7: =COUNTIFS(Data!$L$2:$L$101,$F7,Data!$W$2:$W$101,Data!$W$3) -> 2 | H7: =COUNTIFS(Data!$L$2:$L$101,$F7,Data!$W$2:$W$101,Data!$W$4) -> 13 | I7: =(G7/(G7+H7))*100 -> 13.333333
A10: Cancellation Rate Calculation | I10: total Fast delivery | J10: Total Slow delivery
A11: Region | B11: Cancelled orders | C11: Canceilation Rate | I11: =SUM($G$3:$G$7) -> 11 | J11: =SUM($H$3:$H$7) -> 59
A12: Central | B12: =SUMIFS(Data!$Q$2:$Q$101,Data!$T$2:$T$101,Data!$T$2,Data!$L$2:$L$101,A12) -> 12 | C12: =B12/$C$21 -> 0.13333333
A13: East | B13: =SUMIFS(Data!$Q$2:$Q$101,Data!$T$2:$T$101,Data!$T$2,Data!$L$2:$L$101,A13) -> 10 | C13: =B13/$C$21 -> 0.11111111 | I13: %fast Delivery Total | J13: =$I$11/($I$11+$J$11) -> 0.15714286
A14: North | B14: =SUMIFS(Data!$Q$2:$Q$101,Data!$T$2:$T$101,Data!$T$2,Data!$L$2:$L$101,A14) -> 29 | C14: =B14/$C$21 -> 0.32222222
A15: South | B15: =SUMIFS(Data!$Q$2:$Q$101,Data!$T$2:$T$101,Data!$T$2,Data!$L$2:$L$101,A15) -> 10 | C15: =B15/$C$21 -> 0.11111111
A16: West | B16: =SUMIFS(Data!$Q$2:$Q$101,Data!$T$2:$T$101,Data!$T$2,Data!$L$2:$L$101,A16) -> 29 | C16: =B16/$C$21 -> 0.32222222
H19: cities | I19: cancelled orders | J19: cancellation rate
B21: total cancelled | C21: =SUMIF(Data!$T$2:$T$101,Data!$T$2,Data!$Q$2:$Q$101) -> 90 | E21: Top 3 perfoming region
E23: Region | F23: Sales Target vs Sales Achieved
E24: North | F24: 0.099914286
E25: West | F25: 0.092110193
E26: South | F26: 0.079967213
E29: Region | F29: Sum of Sales Target vs Sales Achieved
E30: North | F30: 0.099914286
E31: South | F31: 0.079967213
E32: West | F32: 0.092110193

Sheet Pivot Tables
A2: CIty vs Sales | E2: Productswise Sales | I2: Effective Sales | M2: Region Vs Category Sales | Q2: Target Sales Vs Achieved Sales Regionwise | U2: Cancellation Rate vs Region | X2: Products Vs Quantity Sold | AB2: Regionwise Fast Delivery%
A3: City | B3: Monthwise Order | C3: Sum of Total Amount | E3: Product Name | F3: Total Quantity | G3: Total Sale Amount | I3: Delivery Status | J3: Region | K3: Sum of Total Amount | M3: Category | N3: Region | O3: Sum of Total Amount | Q3: Region | R3: Sum of Target Sales | S3: Sum of Sales Achieved | U3: Region | V3: Cancelled Rate % | X3: Category | Y3: Product Name | Z3: Sum of Total Amount | AB3: Region | AC3: Sum of Fast Delivery percentage
A4: Austin | C4: 7866 | E4: Smartphone | F4: 12 | G4: 9644 | I4: Delivered | K4: 34 | M4: Home | O4: 10951 | Q4: Central | R4: 97500 | S4: 5456 | U4: North | V4: 0.33333333 | X4: Home | Z4: 10951 | AB4: North | AC4: 0.2
A5: Chicago | C5: 3119 | E5: Cookware Set Pro | F5: 24 | G5: 5151 | J5: North | K5: 4075 | M5: Toys | O5: 3511 | Q5: East | R5: 50500 | S5: 3635 | U5: West | V5: 0.26666667 | Y5: Lamp | Z5: 320 | AB5: South | AC5: 0.1875
A6: Dallas | C6: 367 | E6: Cookware Set | F6: 18 | G6: 2496 | J6: East | K6: 1842 | M6: Fashion | O6: 3872 | Q6: North | R6: 105000 | S6: 10491 | U6: Central | V6: 0.16666667 | Y6: Vacuum Cleaner | Z6: 2144 | AB6: West | AC6: 0.13333333
A7: Miami | C7: 8107 | E7: Smartwatch | F7: 9 | G7: 2230 | J7: South | K7: 1063 | M7: Electronics | O7: 15209 | Q7: South | R7: 91500 | S7: 7317 | U7: South | V7: 0.13333333 | Y7: Wall Clock | Z7: 840 | AB7: East | AC7: 0.13333333
A8: New York | C8: 1040 | E8: Vacuum Cleaner | F8: 11 | G8: 2144 | J8: Central | K8: 3010 | M8: Books | O8: 1715 | Q8: West | R8: 90750 | S8: 8359 | U8: East | V8: 0.1 | Y8: Cookware Set | Z8: 2496 | AB8: Central | AC8: 0.11111111
A9: Phoenix | C9: 2509 | E9: Doll House | F9: 16 | G9: 1530 | J9: West | K9: 3666 | Q9: SUBTOTAL | R9: =SUBTOTAL(9,$R$4:$R$8) -> 435250 | S9: =SUBTOTAL(9,$S$4:$S$8) -> 35258 | Y9: Cookware Set Pro | Z9: 5151
A10: San Francisco | C10: 6396 | E10: Gaming Mouse | F10: 19 | G10: 1392 | X10: Toys | Z10: 3511
A11: Seattle | C11: 5730 | E11: Textbook | F11: 19 | G11: 1318 | Q11: top 1 | R11: =_xlfn.XLOOKUP(MAX($S$4:$S$8),$S$4:$S$8,$Q$4:$Q$8) -> North | S11: =_xlfn.XLOOKUP($R$11,$Q$4:$Q$8,$S$4:$S$8) -> 10491 | Y11: Doll House | Z11: 1530 | AC11: Subtotal % fast delivery
A12: #N/A | C12: 124 | E12: Shoes | F12: 13 | G12: 1239 | Q12: top 2 | R12: =IFERROR(_xlfn.XLOOKUP(LARGE($S$4:$S$8,2),$S$4:$S$8,$Q$4:$Q$8)," ") -> West | S12: =IFERROR(_xlfn.XLOOKUP($R$12,$Q$4:$Q$8,$S$4:$S$8)," ") -> 8359 | Y12: Action Figure | Z12: 669 | AC12: =IFERROR(SUBTOTAL(1,AC4:AC8),"-") -> 0.15305556
E13: Headphones | F13: 7 | G13: 1212 | Q13: top3 | R13: =IFERROR(_xlfn.XLOOKUP(LARGE($S$4:$S$8,3),$S$4:$S$8,$Q$4:$Q$8)," ") -> South | S13: =IFERROR(_xlfn.XLOOKUP($R$13,$Q$4:$Q$8,$S$4:$S$8)," ") -> 7317 | Y13: Puzzle | Z13: 188 | AC13: Most performing region
E14: Leg Set | F14: 18 | G14: 1124 | M14: Delivery Status | N14: Count of Region | Y14: Leg Set | Z14: 1124 | AC14: =$AB$4 -> North
E15: Formal Shirt | F15: 23 | G15: 995 | M15: Cancelled | N15: 0.3 | X15: Fashion | Z15: 3872
E16: Wall Clock | F16: 23 | G16: 840 | M16: Delivered | N16: 0.34 | Y16: Jeans | Z16: 581
E17: Bluetooth Speaker | F17: 7 | G17: 731 | M17: In Transit | N17: 0.36 | Y17: Formal Shirt | Z17: 995
E18: Action Figure | F18: 16 | G18: 669 | Y18: Shoes | Z18: 1239
E19: Jeans | F19: 10 | G19: 581 | Y19: T-Shirt | Z19: 539
E20: T-Shirt | F20: 20 | G20: 539 | Y20: Backpack | Z20: 518
E21: Backpack | F21: 8 | G21: 518 | I21: confirm delivered orders sale | K21: =SUM($K$5:$K$9) -> 13656 | X21: Electronics | Z21: 15209
E22: Lamp | F22: 7 | G22: 320 | Y22: Bluetooth Speaker | Z22: 731
E23: Novel | F23: 11 | G23: 232 | Y23: Smartwatch | Z23: 2230
E24: Puzzle | F24: 6 | G24: 188 | Y24: Gaming Mouse | Z24: 1392
E25: Magazine | F25: 15 | G25: 165 | Y25: Smartphone | Z25: 9644
E26: highest quantity | F26: =MAX($F$4:$F$25) -> 24 | G26: =SUBTOTAL(9,$G$4:$G$25) -> 35258 | H26: total revenue | Y26: Headphones | Z26: 1212
E27: highest seller | F27: =SUBTOTAL(4,G4:G25) -> 9644 | G27: =IFERROR(_xlfn.XLOOKUP($F$27,G4:$G$25,$E$4:$E$25)," ") -> Smartphone | X27: Books | Z27: 1715
Y28: Novel | Z28: 232
Y29: Textbook | Z29: 1318
Y30: Magazine | Z30: 165
I36: confirm delivered orders sale

Sheet Dashboard
A1: Amazon Sales Dashboard

Sheet Insights
A1: 1.What is the most successful product category in terms of revenue? | K1: Top cities with maximum revenue for Smartphone
K2: Product Name | L2: Smartphone
A3: in Categories, Electronics Items generate $ 15209 (43.14 % of total revenue).
A4: In Overall product Category, Smartphone has highest revenue of $ 9644. | K4: City | L4: Sum of Total Amount
A5: For second highest selling product is Cookware set pro with revenue of $ 5151. | K5: Miami | L5: 4886
K6: San Francisco | L6: 3152
A7: Miami city has the highest revenue for smartphone. | K7: Seattle | L7: 1606
K8: Grand Total | L8: 9644
A11: 2. Which region has the highest order cancellation rate?
A13: # North region has highest cancellation rate, about 33.33% of all orders.
A14: # In which, Austin city (40% of total canceled orders) and Seattle city (30% of total canceled orders) has highest cancellation rate.
A15: # Books category orders has the lowest cancellation rate(10%) for all orders while electronics Category has second lowest (13.33%) cancellation rate.
A18: 3.How many orders were delivered within 2 days?
A20: Total numbers of fast delivery orders = 11, with North region has highest (20% )fast delivery rate.
A23: 4.What recommendations would you give to improve delivery performance?
A24: 1 and fast delivery orders within 2 days | F24: 11
A25: For no. of orders delivered within 3 days | F25: =COUNTIF(Data!$V$2:$V$101,"<= 3") -> 19
A26: orders delivered within (3 to 5)days | F26: 15
A28: Most of the orders(6 out of 8) with 3 days delivery are from Austin city of Texas State
A29: so we can improve order delivery to austin City for overall delivery Performance.
A31: monthwise analysing the data(for order delivered within 3 to 5 days) we have found that most delayed delivery are happening for orders taken in october and december months.
A32: As october and december months having more public holidays we can preplan shorter routes of delivery for these months
A33: Also delivery partner with most delay delivery (for total no. of orders delivered within 3 to 5 days) is amazon logistics, we can transfer some orders to other delivery partners to lessen the workload and effective deliveries of orders too.
